Workbook

Sheet QSGR
A1: 14ª BRIGADA DE INFANTARIA MOTORIZADA
A2: "Brigada Silva Paes"
A3: QUADRO DE SOLICITAÇÃO DE GRATIFICAÇÃO DE REPRESENTAÇÃO
A4: Nr: | C4: =CONCATENATE(INFO!C2,"/2025") -> 32/2025
A5: OM: | C5: 63º BI
A6: Evento Pré Autorizado pelo Adt BI CMS?: | C6: SIM | D6: Enquadramento no Adt BI CMS (para eventos pré autorizados) | G6: 185 - Operação Hórus (Faixa de Fronteira).
A7: Amparo Legal
A8: Evento | B8: Descrição do Evento | F8: Atividade do Evento | I8: =_xlfn.IFS(A8=Listas!F3,Listas!H10,A8=Listas!F4,Listas!H11,A8=Listas!F5,Listas!H12,A8=Listas!F5,Listas!H13) -> Amparo
A9: Emprego Operacional | B9: =_xlfn.IFS(A9=Listas!F4,Listas!H4,A9=Listas!F5,Listas!H5,A9=Listas!F6,Listas!H6) -> Atividade realizada por militar da ativa, por meio de designação específica ou como tripulante de embarcação ou aeronave, diretamente relacionada a | F9: I. Operação real ou de adestramento, estabelecida para fins administrativos, operacionais ou logísticos | I9: Inciso III, do Art. 5º do Decreto nº 11.002, de 17 Mar 22. Alíneas a) e b)
A10: Gu Origem | B10: Saída | C10: Dia | D10: Mês | E10: Ano | F10: Hora | G10: Qtd Grat Rep | H10: Bol Int
A11: Florianópolis/SC | C11: =INFO!C4 -> 22 | D11: =INFO!C5 -> 7 | E11: =INFO!C6 -> 2025 | F11: =INFO!C8 -> 0.29166667 | G11: =INFO!C20 -> 33 | H11: =INFO!C9 -> BI Nr 182, de 02/10/2025
A12: Gu Destino | B12: Retorno | C12: Dia | D12: Mês | E12: Ano | F12: Hora
A13: =INFO!C18 -> GUAIRA - PR | C13: =INFO!C12 -> 23 | D13: =INFO!C13 -> 8 | E13: =INFO!C14 -> 2025 | F13: =INFO!C16 -> 0.70833333 | H13: =INFO!C17 -> BI Nr 182, de 02/10/2025
B15: Posto / Grad | D15: Nome | H15: Qtd Grat Rep | I15: Valor 2% | J15: Valor Devido
H16: =$G$11 -> 33 | I16: =_xlfn.IFS(B16="Gen Bda","261,04",B16="Cel","239,32",B16="Ten Cel","235,12",B16="Maj","231,74",B16="1º Ten","172,32",B16="Cap","190,92",B16="2º Ten","156,54",B16="Asp","152,88",B16="SubTen","128,94",B16="1º Sgt","114,60",B16="2º Sgt","99,70",B16="3º Sgt","79,94",B16="Cb","54,90",B16="Al","27,88",B16="Sd EP","36,88",B16="Sd EV","22,54") -> #N/A | J16: =H16*I16 -> #N/A
H17: =$G$11 -> 33 | I17: =_xlfn.IFS(B17="Gen Bda","261,04",B17="Cel","239,32",B17="Ten Cel","235,12",B17="Maj","231,74",B17="1º Ten","172,32",B17="Cap","190,92",B17="2º Ten","156,54",B17="Asp","152,88",B17="SubTen","128,94",B17="1º Sgt","114,60",B17="2º Sgt","99,70",B17="3º Sgt","79,94",B17="Cb","54,90",B17="Al","27,88",B17="Sd EP","36,88",B17="Sd EV","22,54") -> #N/A | J17: =H17*I17 -> #N/A
H18: =$G$11 -> 33 | I18: =_xlfn.IFS(B18="Gen Bda","261,04",B18="Cel","239,32",B18="Ten Cel","235,12",B18="Maj","231,74",B18="1º Ten","172,32",B18="Cap","190,92",B18="2º Ten","156,54",B18="Asp","152,88",B18="SubTen","128,94",B18="1º Sgt","114,60",B18="2º Sgt","99,70",B18="3º Sgt","79,94",B18="Cb","54,90",B18="Al","27,88",B18="Sd EP","36,88",B18="Sd EV","22,54") -> #N/A | J18: =H18*I18 -> #N/A
H19: =$G$11 -> 33 | I19: =_xlfn.IFS(B19="Gen Bda","261,04",B19="Cel","239,32",B19="Ten Cel","235,12",B19="Maj","231,74",B19="1º Ten","172,32",B19="Cap","190,92",B19="2º Ten","156,54",B19="Asp","152,88",B19="SubTen","128,94",B19="1º Sgt","114,60",B19="2º Sgt","99,70",B19="3º Sgt","79,94",B19="Cb","54,90",B19="Al","27,88",B19="Sd EP","36,88",B19="Sd EV","22,54") -> #N/A | J19: =H19*I19 -> #N/A
H20: =$G$11 -> 33 | I20: =_xlfn.IFS(B20="Gen Bda","261,04",B20="Cel","239,32",B20="Ten Cel","235,12",B20="Maj","231,74",B20="1º Ten","172,32",B20="Cap","190,92",B20="2º Ten","156,54",B20="Asp","152,88",B20="SubTen","128,94",B20="1º Sgt","114,60",B20="2º Sgt","99,70",B20="3º Sgt","79,94",B20="Cb","54,90",B20="Al","27,88",B20="Sd EP","36,88",B20="Sd EV","22,54") -> #N/A | J20: =H20*I20 -> #N/A
H21: =$G$11 -> 33 | I21: =_xlfn.IFS(B21="Gen Bda","261,04",B21="Cel","239,32",B21="Ten Cel","235,12",B21="Maj","231,74",B21="1º Ten","172,32",B21="Cap","190,92",B21="2º Ten","156,54",B21="Asp","152,88",B21="SubTen","128,94",B21="1º Sgt","114,60",B21="2º Sgt","99,70",B21="3º Sgt","79,94",B21="Cb","54,90",B21="Al","27,88",B21="Sd EP","36,88",B21="Sd EV","22,54") -> #N/A | J21: =H21*I21 -> #N/A
H22: =$G$11 -> 33 | I22: =_xlfn.IFS(B22="Gen Bda","261,04",B22="Cel","239,32",B22="Ten Cel","235,12",B22="Maj","231,74",B22="1º Ten","172,32",B22="Cap","190,92",B22="2º Ten","156,54",B22="Asp","152,88",B22="SubTen","128,94",B22="1º Sgt","114,60",B22="2º Sgt","99,70",B22="3º Sgt","79,94",B22="Cb","54,90",B22="Al","27,88",B22="Sd EP","36,88",B22="Sd EV","22,54") -> #N/A | J22: =H22*I22 -> #N/A
H23: =$G$11 -> 33 | I23: =_xlfn.IFS(B23="Gen Bda","261,04",B23="Cel","239,32",B23="Ten Cel","235,12",B23="Maj","231,74",B23="1º Ten","172,32",B23="Cap","190,92",B23="2º Ten","156,54",B23="Asp","152,88",B23="SubTen","128,94",B23="1º Sgt","114,60",B23="2º Sgt","99,70",B23="3º Sgt","79,94",B23="Cb","54,90",B23="Al","27,88",B23="Sd EP","36,88",B23="Sd EV","22,54") -> #N/A | J23: =H23*I23 -> #N/A
H24: =$G$11 -> 33 | I24: =_xlfn.IFS(B24="Gen Bda","261,04",B24="Cel","239,32",B24="Ten Cel","235,12",B24="Maj","231,74",B24="1º Ten","172,32",B24="Cap","190,92",B24="2º Ten","156,54",B24="Asp","152,88",B24="SubTen","128,94",B24="1º Sgt","114,60",B24="2º Sgt","99,70",B24="3º Sgt","79,94",B24="Cb","54,90",B24="Al","27,88",B24="Sd EP","36,88",B24="Sd EV","22,54") -> #N/A | J24: =H24*I24 -> #N/A
H25: =$G$11 -> 33 | I25: =_xlfn.IFS(B25="Gen Bda","261,04",B25="Cel","239,32",B25="Ten Cel","235,12",B25="Maj","231,74",B25="1º Ten","172,32",B25="Cap","190,92",B25="2º Ten","156,54",B25="Asp","152,88",B25="SubTen","128,94",B25="1º Sgt","114,60",B25="2º Sgt","99,70",B25="3º Sgt","79,94",B25="Cb","54,90",B25="Al","27,88",B25="Sd EP","36,88",B25="Sd EV","22,54") -> #N/A | J25: =H25*I25 -> #N/A
H26: =$G$11 -> 33 | I26: =_xlfn.IFS(B26="Gen Bda","261,04",B26="Cel","239,32",B26="Ten Cel","235,12",B26="Maj","231,74",B26="1º Ten","172,32",B26="Cap","190,92",B26="2º Ten","156,54",B26="Asp","152,88",B26="SubTen","128,94",B26="1º Sgt","114,60",B26="2º Sgt","99,70",B26="3º Sgt","79,94",B26="Cb","54,90",B26="Al","27,88",B26="Sd EP","36,88",B26="Sd EV","22,54") -> #N/A | J26: =H26*I26 -> #N/A
H27: =$G$11 -> 33 | I27: =_xlfn.IFS(B27="Gen Bda","261,04",B27="Cel","239,32",B27="Ten Cel","235,12",B27="Maj","231,74",B27="1º Ten","172,32",B27="Cap","190,92",B27="2º Ten","156,54",B27="Asp","152,88",B27="SubTen","128,94",B27="1º Sgt","114,60",B27="2º Sgt","99,70",B27="3º Sgt","79,94",B27="Cb","54,90",B27="Al","27,88",B27="Sd EP","36,88",B27="Sd EV","22,54") -> #N/A | J27: =H27*I27 -> #N/A
... H153: =$G$11 -> 33 | I153: =_xlfn.IFS(B153="Gen Bda","261,04",B153="Cel","239,32",B153="Ten Cel","235,12",B153="Maj","231,74",B153="1º Ten","172,32",B153="Cap","190,92",B153="2º Ten","156,54",B153="Asp","152,88",B153="SubTen","128,94",B153="1º Sgt","114,60",B153="2º Sgt","99,70",B153="3º Sgt","79,94",B153="Cb","54,90",B153="Al","27,88",B153="Sd EP","36,88",B153="Sd EV","22,54") -> #N/A | J153: =H153*I153 -> #N/A
B154: Total | J154: =SUM(J16:J53) -> #N/A
B155: =CONCATENATE("Observações ligadas à missão: Deslocamento para a cidade de ",$A$13,", com a finalidade ",INFO!$B$22) -> Observações ligadas à missão: Deslocamento para a cidade de GUAIRA - PR, com a finalidade PARTICIPAR DA OPERAÇÃO HORUS.
A158: Florianópolis – SC | C158: LUIS HENRIQUE VIGHI TEIXEIRA – CEL
A159: =" " & DAY(TODAY()) & " de " & TEXT(TODAY(),"MMMM") & " de " & YEAR(TODAY()) -> 26 de novembro de 2025 | C159: Comandante do 63º BI

Sheet INFO
A2: NÚMERO | C2: 32
A4: SAÍDA | B4: DIA | C4: 22
B5: MES | C5: 7
B6: ANO | C6: 2025
B7: HORA | C7: 700
C8: =TIME(INT(C7/100),MOD(C7,100),0) -> 0.29166667
B9: BI | C9: BI Nr 182, de 02/10/2025
B10: CONCATENADO | C10: =CONCATENATE(C4,"/",C5,"/",C6," ",) -> 22/7/2025
A11: =C16-C8 -> 0.41666667 | B11: 0.33333333 | C11: =IF(A11<B11,0,1) -> 1
A12: CHAGADA | B12: DIA | C12: 23
B13: MES | C13: 8
B14: ANO | C14: 2025
B15: HORA | C15: 1700
B16: HORA | C16: =TIME(INT(C15/100),MOD(C15,100),0) -> 0.70833333
B17: BI | C17: BI Nr 182, de 02/10/2025
B18: CIDADE | C18: GUAIRA - PR
B19: CONCATENADO | C19: =CONCATENATE(C12,"/",C13,"/",C14," ",) -> 23/8/2025
B20: DIAS | C20: =(C19-C10)+C11 -> 33
A22: FINALIDADE | B22: PARTICIPAR DA OPERAÇÃO HORUS.
A24: DIEx Btl | B24: TESTE AZUL
A26: DIEx Bda | B26: TESTE VERMELHO

Sheet NotaBar
B1: =CONCATENATE("Foi autorizado o saque de gratificação de representação referente ao QSGR ",INFO!C2,", de ",QSGR!$A$80," (Deslocamento para ",INFO!C18,", com a finalidade de ",INFO!B22,", conforme informação contida no ",INFO!B26,INFO!D26,", aos seguintes militares nas condições abaixo: ") -> Foi autorizado o saque de gratificação de representação referente ao QSGR 32, de (Deslocamento para GUAIRA - PR, com a finalidade de PARTICIPAR DA OPERAÇÃO HORUS., conforme informação contida no TESTE VERMELHO, aos seguintes militares nas condições abaixo:
B8: MILITAR | AC8: 1
B9: =INDEX(QSGR!$B$16:$B$1570,AC8) -> 0 | E9: =INDEX(QSGR!$D$16:$D$11170,AC8) -> 0
B10: =CONCATENATE("- Evento: ",INFO!$B$22) -> - Evento: PARTICIPAR DA OPERAÇÃO HORUS.
B11: =CONCATENATE("- Documento de Solicitação: ",INFO!$B$24) -> - Documento de Solicitação: TESTE AZUL
B12: =CONCATENATE("- Local: ",INFO!$C$18) -> - Local: GUAIRA - PR
B13: =CONCATENATE("- Periodo: ",INFO!$C$10," a ",INFO!$C$19) -> - Periodo: 22/7/2025 a 23/8/2025
B14: =CONCATENATE("- Nr Dias: ",INFO!$C$20) -> - Nr Dias: 33
B15: =CONCATENATE("- Valor Estimado: R$ ",INDEX(QSGR!$J$16:$J$11170,AC8)) -> #N/A
B17: MILITAR | AC17: 2
B18: =INDEX(QSGR!$B$16:$B$1570,AC17) -> 0 | E18: =INDEX(QSGR!$D$16:$D$11170,AC17) -> 0
B19: =CONCATENATE("- Evento: ",INFO!$B$22) -> - Evento: PARTICIPAR DA OPERAÇÃO HORUS.
B20: =CONCATENATE("- Documento de Solicitação: ",INFO!$B$24) -> - Documento de Solicitação: TESTE AZUL
B21: =CONCATENATE("- Local: ",INFO!$C$18) -> - Local: GUAIRA - PR
B22: =CONCATENATE("- Periodo: ",INFO!$C$10," a ",INFO!$C$19) -> - Periodo: 22/7/2025 a 23/8/2025
B23: =CONCATENATE("- Nr Dias: ",INFO!$C$20) -> - Nr Dias: 33
B24: =CONCATENATE("- Valor Estimado: R$ ",INDEX(QSGR!$J$16:$J$11170,AC17)) -> #N/A
B26: MILITAR | AC26: 3
B27: =INDEX(QSGR!$B$16:$B$1570,AC26) -> 0 | E27: =INDEX(QSGR!$D$16:$D$11170,AC26) -> 0
B28: =CONCATENATE("- Evento: ",INFO!$B$22) -> - Evento: PARTICIPAR DA OPERAÇÃO HORUS.
B29: =CONCATENATE("- Documento de Solicitação: ",INFO!$B$24) -> - Documento de Solicitação: TESTE AZUL
B30: =CONCATENATE("- Local: ",INFO!$C$18) -> - Local: GUAIRA - PR
B31: =CONCATENATE("- Periodo: ",INFO!$C$10," a ",INFO!$C$19) -> - Periodo: 22/7/2025 a 23/8/2025
B32: =CONCATENATE("- Nr Dias: ",INFO!$C$20) -> - Nr Dias: 33
B33: =CONCATENATE("- Valor Estimado: R$ ",INDEX(QSGR!$J$16:$J$11170,AC26)) -> #N/A
B35: MILITAR | AC35: 4
B36: =INDEX(QSGR!$B$16:$B$1570,AC35) -> 0 | E36: =INDEX(QSGR!$D$16:$D$11170,AC35) -> 0
B37: =CONCATENATE("- Evento: ",INFO!$B$22) -> - Evento: PARTICIPAR DA OPERAÇÃO HORUS.
B38: =CONCATENATE("- Documento de Solicitação: ",INFO!$B$24) -> - Documento de Solicitação: TESTE AZUL
B39: =CONCATENATE("- Local: ",INFO!$C$18) -> - Local: GUAIRA - PR
B40: =CONCATENATE("- Periodo: ",INFO!$C$10," a ",INFO!$C$19) -> - Periodo: 22/7/2025 a 23/8/2025
B41: =CONCATENATE("- Nr Dias: ",INFO!$C$20) -> - Nr Dias: 33
B42: =CONCATENATE("- Valor Estimado: R$ ",INDEX(QSGR!$J$16:$J$11170,AC35)) -> #N/A
B44: MILITAR | AC44: 5
B45: =INDEX(QSGR!$B$16:$B$1570,AC44) -> 0 | E45: =INDEX(QSGR!$D$16:$D$11170,AC44) -> 0
B46: =CONCATENATE("- Evento: ",INFO!$B$22) -> - Evento: PARTICIPAR DA OPERAÇÃO HORUS.
B47: =CONCATENATE("- Documento de Solicitação: ",INFO!$B$24) -> - Documento de Solicitação: TESTE AZUL
B48: =CONCATENATE("- Local: ",INFO!$C$18) -> - Local: GUAIRA - PR
B49: =CONCATENATE("- Periodo: ",INFO!$C$10," a ",INFO!$C$19) -> - Periodo: 22/7/2025 a 23/8/2025
B50: =CONCATENATE("- Nr Dias: ",INFO!$C$20) -> - Nr Dias: 33
...

Sheet Listas
B2: SIM | D2: Eventos Pré Autorizados CMS
B3: NÃO | D3: 0. Evento Sem Pré Autorização | F3: Evento | H3: Descrição do Evento | J3: Atividade do Evento
D4: 1 - Adestramento Básico em Ambiente Virtual - CI Bld; | F4: Viagem de Representação | H4: Deslocamento realizado por militar da ativa para fora de sua sede, por interesse da instituição, na condição de representante do MD ou dos Comandos das Forças, para participação em eventos de natureza militar ou civil, inclusive os de cunho cultural ou desportivo | J4: A. Representação por determinação de autoridade competente
D5: 2 - Adestramento de Corneteiro e Clarins fora da sede | F5: Viagem de Instrução | H5: Atividade realizada por militar da ativa fora de sua sede, cujo objetivo esteja relacionado com ensino ou instrução, orientação técnica ou inspeção de comando | J5: B. Competições Desportivas Hípicas, oficiais, previstas no Calendário do Programa Desportivo do Exército Brasileiro
D6: 3 - Ap Def Civ - 14ª Bda Inf Mtz - Exc Ajuda Humanitária | F6: Emprego Operacional | H6: Atividade realizada por militar da ativa, por meio de designação específica ou como tripulante de embarcação ou aeronave, diretamente relacionada a | J6: C. Eventos e exercícios no terreno, fora de sede
D7: 4 - Apanha de Suprimento Classe I, II e V - fora da sede, | J7: D. PCI realizados fora de sede da OM
D8: 5 - Apoio de Comunicações, na composição do CCOP da 3ª DE, | J8: E. Militares de outras OM que apoiaram, fora de sede, os eventos e exercícios de terreno
D9: 6 - Apoio de Pessoal ao Setor de Aprovisionamento em formaturas e ou eventos realizados em localidades fora da sede. | J9: F. Viagem de Orientação Técnica
A10: SOLDOS | D10: 7 - Apoio de Polícia do Exército - Segurança de Autoridade / Instalações/Emprego de cães (faro); | H10: Amparo | J10: G. Inspeções de instrução previstas no Plano de Instrução Militar do COTER (PIM/COTER) e na Diretriz de Instrução Militar (DIM)
A11: Gen Bda | B11: 261.04 | D11: 8 - Apoio de saúde em Ação Civico-Social, em Pericia Contábil, em Pericia Judicial, como Assistente Técnico da União em Pericia Judicial e como | H11: Inciso I, do Art. 5º do Decreto nº 11.002, de 17 Mar 22. | J11: H. Atividades logísticas e administrativas previstas no calendário da 4ª Seção, inclusive Apoio Logístio de Pessoal
A12: Cel | B12: 239.32 | D12: 9 - Apoio Direto de Comunicação Social e Cobertura Midiática fora da sede, | H12: Inciso II, do Art. 5º do Decreto nº 11.002, de 17 Mar 22. | J12: I. Operação real ou de adestramento, estabelecida para fins administrativos, operacionais ou logísticos
A13: Ten Cel | B13: 235.12 | D13: 10 - Apoio Direto de Manutenção Logística; | H13: Inciso III, do Art. 5º do Decreto nº 11.002, de 17 Mar 22. Alíneas a) e b) | J13: J. Ações militares de vigilância de fronteira destinadas à preservação da integridade territorial do País e à garantia da soberania nacional desenvolvidas por militares que componham o efetivo de pelotões especiais de fronteira ou de destacamento especiais de fronteira
A14: Maj | B14: 231.74 | D14: 11 - Apoio Direto de Serviço de Engenharia fora da sede; | H14: Inciso III, do Art. 5º do Decreto nº 11.002, de 17 Mar 22. Alínea c) | J14: K. Ações militares de operações de garantia da lei e da ordem, de que trata o art. 15 da Lei Complementar nº 97, de 9 de junho de 1999
A15: Cap | B15: 190.92 | D15: 12 - Apoio Direto de Transporte de Material por rodovias para fora da sede, | H15: Inciso III, do Art. 5º do Decreto nº 11.002, de 17 Mar 22. Alínea d) | J15: L. Ações relacionadas às atribuições subsidiárias das Forças armadas, de que tratam a art. 16, o 16-A e o inciso VI do caput do art 18 da Lei Complementar nº 97, de 1999
A16: 1º Ten | B16: 172.32 | D16: 13 - Apoio Direto de Transporte de Pessoal por rodovias para fora da sede, | H16: Inciso III, do Art. 5º do Decreto nº 11.002, de 17 Mar 22. Alínea e) | J16: M. Adestramento para participação em missões de paz
A17: 2º Ten | B17: 156.54 | D17: 14 - Apoio Direto em Diligências (IPM/Sindicâncias) fora da sede; | H17: Inciso III, do Art. 5º do Decreto nº 11.002, de 17 Mar 22. Alínea f) | J17: N. Participação, fora de sede, em serviços de engenharia
A18: Asp | B18: 152.88 | D18: 15 - Apoio e Serviços de Engenharia, fora da sede | J18: O. Participação, fora de sede, em serviços de cartografia
A19: SubTen | B19: 128.94 | D19: 16 - Apoio logístico de transporte de pessoal, fora da sede da OM; | J19: P. Participação, fora de sede, em levantamento topográfico
A20: 1º Sgt | B20: 114.6 | D20: 17 - Apoio logístico no transporte de material de emprego militar, fora do quartel-general da OM, - | J20: Q. Participação, fora de sede, em escolta
A21: 2º Sgt | B21: 99.7 | D21: 18 - Apoio médico veterinário em temporadas hípicas; | J21: R. Participação, fora de sede, em perícia
A22: 3º Sgt | B22: 79.94 | D22: 19 - Apoio na realização de Exames Psicológicos dos candidatos ao Curso de Formação e Graduação de Sargentos do Exército (CFGS 2024/2025), | J22: S. Participação, fora de sede, em geoinformação
A23: Al | B23: 27.88 | D23: 20 - Atividade Administrativa de Emissão de Certificado Digital; | J23: T. Participação, fora de sede, em implantação e manutenção da infraestrutura de tecnologia de comunicações
A24: Cb | B24: 54.9 | D24: 21 - Atividade de Acompanhamento da Preparação (fase 1) - FORPRON; | J24: U. Participação, fora de sede, em avaliação de sistemas e materiais de emprego militar e de produtos de defesa
A25: Sd EP | B25: 36.88 | D25: 22 - Atividade de Apoio ao Adestramento e Apoio a Certificação, | J25: V. Participação, fora de sede, em atividades relacionadas à manutenção
A26: Sd EV | B26: 22.54 | D26: 23 - Atividade de Assistência Social;
D27: 24 - Atividade de Campanha do Curso de Formação de Cabos (CFC);
D28: 25 - Atividade de Campanha do Estágio Básico de Oficial Técnico Temporário (EBOT);
D29: 26 - Atividade de Campanha do Estágio Básico de Sargento Temporário (EBST);
D30: 27 - Atividade de Campanha do NPOR,
D31: 28 - Atividade de Diligências de PE, fora da sede;
D32: 29 - Atividade de Escolta em Motocicletas PE nas Visitas de Autoridades - fora da sede, - Atividade de Troca de Motocicletas PE entre as OMPE - fora da sede,
D33: 30 - Atividade Relacionada com Apresentação Institucional da Banda de Música fora da sede;
D34: 31 - Atividade Relacionada com Comissão de Seleção Complementar fora da sede,
D35: 32 - Atividade Relacionada com Inspeção de Saúde de militares em OMSau fora da sede;
D36: 33 - Atividades da Comissão de Seleção fora da Sede;
D37: 34 - Atividades da Semana da Pátria,
D38: 35 - Atividades de Operações de Informação - fora da sede,
... D261: 258 - Workshop Gestão da Frota:

Sheet Modelo Nota para BI
B1: IDA
B2: Deslocou-se de Brasília/DF para Recife/PE, em 16 MAI 25 (Ida)
B3: Atividade: Realizar Exercício de Longa Duração do Curso Básico de Inteligência para Sargentos 2025
B4: Militares:
B5: 2º SGT CARLOS GARCIA JUNIOR
B7: Outras informações julgadas necessárias pela OM para melhor detalhar a missão
B9: RETORNO
B10: Deslocou-se de Recife/PE para Brasília/DF, em 24 MAI 25 (Ida)
B11: Atividade: Retornar do Exercício de Longa Duração do Curso Básico de Inteligência para Sargentos 2025
B12: Militares:
B13: 2º SGT CARLOS GARCIA JUNIOR
B14: Outras informações julgadas necessárias pela OM para melhor detalhar a missão

Sheet Indície
A1: QSGR | C1: LINK
A2: 1 | C2: QSGR 01
A3: 2 | C3: QSGR 02
A4: 3 | C4: QSGR 03
A5: 4 | C5: QSGR 04
A6: 5 | C6: QSGR 05
A7: 6 | C7: QSGR 06
A8: 7 | C8: QSGR 07
A9: 8 | C9: NÃO POSSUI
A10: 9 | C10: QSGR 09
A11: 10 | C11: QSGR 10
A12: 11 | C12: QSGR 11
A13: 12 | C13: QSGR 12
... A44: 43 | C44: QSGR Nr 43
A45: 44
A46: 45
A47: 46
A48: 47
A49: 48
A50: 49
A51: 50
A52: 51
A53: 52
A54: 53
A55: 54
A56: 55
... A100: 99

Sheet Planilha7
A1: 1 - | B1: Adestramento Básico em Ambiente Virtual - CI Bld; | C1: =CONCATENATE(A1,B1) -> 1 - Adestramento Básico em Ambiente Virtual - CI Bld;
A2: 2 - | B2: Adestramento de Corneteiro e Clarins fora da sede,tinuação do Aditamento Administrativo nº 04 ao Boletim do CMS nº 09, de 05 de Março 25) | C2: =CONCATENATE(A2,B2) -> 2 - Adestramento de Corneteiro e Clarins fora da sede,tinuação do Aditamento Administrativo nº 04 ao Boletim do CMS nº 09, de 05 de Março 25)
A3: 3 - | B3: Ap Def Civ - 14ª Bda Inf Mtz - Exc Ajuda Humanitária | C3: =CONCATENATE(A3,B3) -> 3 - Ap Def Civ - 14ª Bda Inf Mtz - Exc Ajuda Humanitária
A4: 4 - | B4: Apanha de Suprimento Classe I, II e V - fora da sede, | C4: =CONCATENATE(A4,B4) -> 4 - Apanha de Suprimento Classe I, II e V - fora da sede,
A5: 5 - | B5: Apoio de Comunicações, na composição do CCOP da 3ª DE, | C5: =CONCATENATE(A5,B5) -> 5 - Apoio de Comunicações, na composição do CCOP da 3ª DE,
A6: 6 - | B6: Apoio de Pessoal ao Setor de Aprovisionamento em formaturas e ou eventos realizados em localidades fora da sede. | C6: =CONCATENATE(A6,B6) -> 6 - Apoio de Pessoal ao Setor de Aprovisionamento em formaturas e ou eventos realizados em localidades fora da sede.
A7: 7 - | B7: Apoio de Polícia do Exército - Segurança de Autoridade / Instalações/Emprego de cães (faro); | C7: =CONCATENATE(A7,B7) -> 7 - Apoio de Polícia do Exército - Segurança de Autoridade / Instalações/Emprego de cães (faro);
A8: 8 - | B8: Apoio de saúde em Ação Civico-Social, em Pericia Contábil, em Pericia Judicial, como Assistente Técnico da União em Pericia Judicial e como | C8: =CONCATENATE(A8,B8) -> 8 - Apoio de saúde em Ação Civico-Social, em Pericia Contábil, em Pericia Judicial, como Assistente Técnico da União em Pericia Judicial e como
A9: 9 - | B9: Apoio Direto de Comunicação Social e Cobertura Midiática fora da sede, | C9: =CONCATENATE(A9,B9) -> 9 - Apoio Direto de Comunicação Social e Cobertura Midiática fora da sede,
A10: 10 - | B10: Apoio Direto de Manutenção Logística; | C10: =CONCATENATE(A10,B10) -> 10 - Apoio Direto de Manutenção Logística;
A11: 11 - | B11: Apoio Direto de Serviço de Engenharia fora da sede; | C11: =CONCATENATE(A11,B11) -> 11 - Apoio Direto de Serviço de Engenharia fora da sede;
A12: 12 - | B12: Apoio Direto de Transporte de Material por rodovias para fora da sede, | C12: =CONCATENATE(A12,B12) -> 12 - Apoio Direto de Transporte de Material por rodovias para fora da sede,
... A258: 258 - | B258: Workshop Gestão da Frota: | C258: =CONCATENATE(A258,B258) -> 258 - Workshop Gestão da Frota:
